Workbook

Sheet Sheet 1
A1: Period Ending: | H1: 2021 | I1: 2022 | J1: 2023 | K1: 2024 | L1: 2025
H2: 45747 | I2: 45747 | J2: 45747 | K2: 45747 | L2: 45747
B3: Total Revenues | H3: 1393264.2 | I3: 1587505.7 | J3: 1861940.4 | K3: 2251889.9 | L3: 2598063.1
B5: Total Revenues Growth | H5: -0.0575 | I5: 0.1394 | J5: 0.1729 | K5: 0.2094 | L5: 0.1537
B7: Cost Of Revenues | H7: 872385.2 | I7: 973808.7 | J7: 1134006.3 | K7: 1412145.9 | L7: 1648291.2
B9: Gross Profit | H9: 520879 | I9: 613697 | J9: 727934.1 | K9: 839744 | L9: 949771.9
B11: Gross Profit Growth | H11: 0.0455 | I11: 0.1782 | J11: 0.1861 | K11: 0.1536 | L11: 0.131
B13: Gross Profit Margin % | H13: 0.3739 | I13: 0.3866 | J13: 0.391 | K13: 0.3729 | L13: 0.3656
B15: Other Operating Expenses, Total | H15: 359103.1 | I15: 438536.4 | J15: 525565.3 | K15: 600709.3 | L15: 685611
B16: Other Operating Expenses, Total Growth | H16: 0.0706 | I16: 0.2212 | J16: 0.1985 | K16: 0.143 | L16: 0.1413
B17: R&D Expenses | H17: - | I17: - | J17: - | K17: - | L17: -
B18: Selling General & Admin Expenses | H18: 331164.1 | I18: 409357.5 | J18: 491867.9 | K18: 564046.7 | L18: 644705.9
B19: Other Operating Expenses | H19: -193.5 | I19: -201.4 | J19: -144.6 | K19: -84.4 | L19: -77.1
B20: Operating Income | H20: 161775.9 | I20: 175160.6 | J20: 202368.8 | K20: 239034.7 | L20: 264160.9
B22: Operating Income Growth | H22: -0.0063 | I22: 0.0827 | J22: 0.1553 | K22: 0.1812 | L22: 0.1051
B24: EBIT Margin % | H24: 0.1161 | I24: 0.1103 | J24: 0.1087 | K24: 0.1061 | L24: 0.1017
B26: Net Interest Expenses | H26: -39045.4 | I26: -30554.2 | J26: -31776.8 | K26: -35365.1 | L26: -33308.4
B28: Net Interest Expenses Growth | H28: -0.4338 | I28: 0.2175 | J28: -0.04 | K28: -0.1129 | L28: 0.0582
B30: Interest Expense, Total | H30: -39045.4 | I30: -30554.2 | J30: -31776.8 | K30: -35365.1 | L30: -33308.4
B32: Interest And Investment Income | H32: - | I32: - | J32: - | K32: - | L32: -
B34: Other Non Operating Expenses, Total | H34: 55 | I34: 579.1 | J34: -1237.3 | K34: -319.6 | L34: -175.9
B36: EBT, Excl. Unusual Items | H36: 122785.5 | I36: 145185.5 | J36: 169354.7 | K36: 203350 | L36: 230676.6
B38: Gain (Loss) On Sale Of Assets | H38: 626.1 | I38: 176 | J38: 613.7 | K38: 735.1 | L38: 452.5
B40: Other Unusual Items, Total | H40: -891.4 | I40: -99.2 | J40: -1180.5 | K40: -76.3 | L40: -229.6
B42: EBT, Incl. Unusual Items | H42: 122502 | I42: 145262.3 | J42: 168787.9 | K42: 204008.8 | L42: 230899.5
B44: EBT, Incl. Unusual Items Growth | H44: -0.0928 | I44: 0.1858 | J44: 0.162 | K44: 0.2087 | L44: 0.1318
B46: EBT, Incl. Unusual Items Margin | H46: 0.0879 | I46: 0.0915 | J46: 0.0907 | K46: 0.0906 | L46: 0.0889
B48: Income Tax Expense | H48: 40108.2 | I48: 42039.2 | J48: 44841.6 | K48: 49473.9 | L48: 58914
B50: Net Income to Company | H50: 129212.8 | I50: 104192.4 | J50: 125306.2 | K50: 155471 | L50: 176733.3
B52: Minority Interest | H52: -13383.5 | I52: -17499.1 | J52: -20599 | K52: -24879.9 | L52: -26362.2
B54: Net Income | H54: 115829.3 | I54: 86693.3 | J54: 104707.2 | K54: 130591.1 | L54: 150371.1
B56: Net Income Growth | H56: 0.213 | I56: -0.2515 | J56: 0.2078 | K56: 0.2472 | L56: 0.1515
B58: Net Income Margin % | H58: 0.0831 | I58: 0.0546 | J58: 0.0562 | K58: 0.058 | L58: 0.0579
B60: Preferred Dividend and Other Adjustments | H60: - | I60: - | J60: - | K60: - | L60: -
B62: Net Income to Common Excl. Extra Items | H62: 69010.3 | I62: 85724 | J62: 103347.3 | K62: 129655 | L62: 145623.3
B64: Basic EPS - Continuing Operations | H64: 49.15 | I64: 61.02 | J64: 73.54 | K64: 93.29 | L64: 105.91
B66: Basic EPS - Continuing Operations Growth | H66: -0.2245 | I66: 0.2417 | J66: 0.2051 | K66: 0.2685 | L66: 0.1353
B68: Diluted EPS - Continuing Operations | H68: 49.1 | I68: 60.96 | J68: 73.48 | K68: 93.21 | L68: 105.83
B70: Diluted EPS - Continuing Operations Growth | H70: -0.2242 | I70: 0.2416 | J70: 0.2054 | K70: 0.2684 | L70: 0.1354
B72: Basic Weighted Average Shares Outstanding | H72: 1404.15 | I72: 1404.75 | J72: 1405.26 | K72: 1389.82 | L72: 1374.99
...

Sheet Sheet 2
A1: Period Ending: | H1: 2021 | I1: 2022 | J1: 2023 | K1: 2024 | L1: 2025
H2: 45747 | I2: 45747 | J2: 45747 | K2: 45747 | L2: 45747
B3: Total Current Assets | H3: 1949668.3 | I3: 2082030.8 | J3: 2222043.2 | K3: 2185886 | L3: 2453417.1
B4: Cash And Equivalents | H4: 133735.2 | I4: 137702.4 | J4: 169266.9 | K4: 119585 | L4: 121870
B5: Cash And Equivalents Growth | H5: 0.1809 | I5: 0.0297 | J5: 0.2292 | K5: -0.2935 | L5: 0.0191
B6: Short Term Investments | H6: 316277.2 | I6: 322617.8 | J6: 375106.1 | K6: 366737.6 | L6: 484070.1
B7: Total Receivables | H7: 910244.1 | I7: 1006981.9 | J7: 1039780.8 | K7: 1137303 | L7: 1192515.7
B8: Accounts Receivable, Total | H8: 906868.5 | I8: 995465.3 | J8: 1019526.9 | K8: 1108214.2 | L8: 1172380.5
B9: Other Receivables | H9: 1022.1 | I9: 8713.2 | J9: 17742.4 | K9: 28023.4 | L9: 15966.7
B10: Inventory | H10: 58205.4 | I10: 59433.2 | J10: 68287.8 | K10: 66201.9 | L10: 76705.5
B11: Prepaid Expenses | H11: - | I11: - | J11: - | K11: - | L11: -
B12: Finance Division Loans and Leases Current | H12: 413790.3 | I12: 422692 | J12: 404605.5 | K12: 348145.9 | L12: 360775.1
B13: Finance Division Other Current Assets, Total | H13: - | I13: - | J13: - | K13: - | L13: -
B14: Other Current Assets | H14: 117416.1 | I14: 132603.5 | J14: 164996.1 | K14: 147912.6 | L14: 217480.7
B15: Restricted Cash | H15: 11710.5 | I15: 10165.6 | J15: 7900.6 | K15: 6049.9 | L15: 8592.2
B16: Other Current Assets, Total | H16: 105705.6 | I16: 122437.9 | J16: 157095.5 | K16: 141862.7 | L16: 208888.5
B17: Total Assets | H17: 3112737.1 | I17: 3200672.4 | J17: 3303523.1 | K17: 3401359.7 | L17: 3795241
B18: Total Assets Growth | H18: 0.0102 | I18: 0.0283 | J18: 0.0321 | K18: 0.0296 | L18: 0.1158
B19: Net Property Plant And Equipment | H19: 137961.9 | I19: 137378.1 | J19: 164232.4 | K19: 184840.9 | L19: 193884.4
B20: Gross Property Plant And Equipment | H20: 220077.7 | I20: 231116.8 | J20: 272999.6 | K20: 308637.2 | L20: 339066.1
B21: Accumulated Depreciation | H21: -82115.8 | I21: -93738.7 | J21: -108767.2 | K21: -123796.3 | L21: -145181.7
B22: Long-term Investments | H22: 88434.7 | I22: 104276.2 | J22: 102742.4 | K22: 111687.1 | L22: 116700.9
B23: Intangible Assets | H23: 273753.8 | I23: 264929.1 | J23: 259227.4 | K23: 253326.2 | L23: 255967.7
B24: Goodwill | H24: 80669.6 | I24: 76851.7 | J24: 77986.5 | K24: 78008.8 | L24: 83484.8
B25: Other Intangibles, Total | H25: 193084.2 | I25: 188077.4 | J25: 181240.9 | K25: 175317.4 | L25: 172482.9
... B28: Loans Receivable Long-Term | H28: 1732.4 | I28: 2845.4 | J28: 3560 | K28: 4754.6 | L28: 3489.6
B29: Accounts Receivable Long-Term | H29: - | I29: - | J29: - | K29: - | L29: -
B30: Deferred Tax Assets Long-Term | H30: 26970 | I30: 28401 | J30: 39847.9 | K30: 38637.2 | L30: 37928.8
B31: Deferred Charges Long-Term | H31: 13.6 | I31: 8.6 | J31: 3.7 | K31: 7.5 | L31: 2.9
B32: Other Long-Term Assets, Total | H32: 107885.7 | I32: 113434.8 | J32: 102656.9 | K32: 100672.6 | L32: 105376.1
B33: Total Current Liabilities | H33: 1374080.1 | I33: 1594405.8 | J33: 1620659.9 | K33: 1771094.6 | L33: 2019709
B34: Accounts Payable, Total | H34: 457452.3 | I34: 513656.2 | J34: 497841.2 | K34: 532928.8 | L34: 524593.4
B35: Accrued Expenses, Total | H35: 18792.2 | I35: 20387.2 | J35: 21246.6 | K35: 21172 | L35: 26149.9
B36: Short-term Borrowings | H36: 277658.3 | I36: 304769.6 | J36: 308963.2 | K36: 278342.7 | L36: 358613
B37: Current Portion of Long-Term Debt / Leases | H37: 231254.9 | I37: 317795 | J37: 268901.3 | K37: 302462 | L37: 367790.4
B38: Current Portion of Long-Term Debt | H38: 227193.9 | I38: 313729.6 | J38: 263993.8 | K38: 296985.3 | L38: 361947
B39: Current Portion of Leases | H39: 4061 | I39: 4065.4 | J39: 4907.5 | K39: 5476.7 | L39: 5843.4
B40: Other Current Liabilities, Total | H40: 388922.4 | I40: 437797.8 | J40: 523707.6 | K40: 636189.1 | L40: 742562.3
B41: Current Income Taxes Payable | H41: 11710.2 | I41: 13098.2 | J41: 13934.6 | K41: 18604.7 | L41: 25792.1
... B48: Other Liabilities, Total | H48: 22078.8 | I48: 20013.1 | J48: 18551.1 | K48: 22351 | L48: 23809.4
...

Sheet Sheet 3
A1: Period Ending: | H1: 2021 | I1: 2022 | J1: 2023 | K1: 2024 | L1: 2025
H2: 45747 | I2: 45747 | J2: 45747 | K2: 45747 | L2: 45747
B3: Cash from Operations | H3: 230719.6 | I3: 191635.8 | J3: 227769.6 | K3: 182662.8 | L3: 91607.1
B4: Cash from Operations Growth | H4: 2.5265 | I4: -0.1694 | J4: 0.1886 | K4: -0.198 | L4: -0.4985
B5: Net Income | H5: 115829.3 | I5: 86693.3 | J5: 104707.2 | K5: 130591.1 | L5: 150371.1
B6: Depreciation & Amortization, Total | H6: 28134.8 | I6: 29380.3 | J6: 33842 | K6: 34437.8 | L6: 38756.1
B7: Amortization of Deferred Charges, Total | H7: - | I7: - | J7: - | K7: 2309.2 | L7: 2226.1
B8: Other Non-Cash Items, Total | H8: -15223.5 | I8: 27995.9 | J8: 35429 | K8: 29175.5 | L8: 20893.3
B9: Change in Net Operating Assets | H9: 101979 | I9: 47566.3 | J9: 53791.4 | K9: -13850.8 | L9: -120639.5
B10: Cash from Investing | H10: -56585.2 | I10: -36676.8 | J10: -83117 | K10: 21630.4 | L10: -155175.1
B11: Cash from Investing Growth | H11: 0.3146 | I11: 0.3518 | J11: -1.2662 | K11: 1.2602 | L11: -8.1739
B12: Capital Expenditure | H12: -18077 | I12: -31106.3 | J12: -41437.9 | K12: -45165.3 | L12: -44188.3
B13: Sale of Property, Plant, and Equipment | H13: 8853.6 | I13: 707.5 | J13: 3503.7 | K13: 3060.6 | L13: 8781.7
B14: Cash Acquisitions | H14: -1147 | I14: -779.4 | J14: -1245.6 | K14: -131.3 | L14: -10201.4
B15: Divestitures | H15: 3094.7 | I15: 9506.6 | J15: 28724.3 | K15: 8610.3 | L15: 17521.1
B16: Other Investing Activities | H16: -49309.5 | I16: -15005.2 | J16: -72661.5 | K16: 55256.1 | L16: -127088.2
B17: Cash from Financing | H17: -152743.8 | I17: -151814.8 | J17: -115724.9 | K17: -254133.6 | L17: 65566.2
B18: Cash from Financing Growth | H18: -3.3973 | I18: 0.0061 | J18: 0.2377 | K18: -1.196 | L18: 1.258
B19: Total Debt Issued | H19: 362586 | I19: 273932.6 | J19: 282983.3 | K19: 231254.3 | L19: 464970.1
B20: Short Term Debt Issued, Total | H20: - | I20: - | J20: 3574 | K20: - | L20: -
B21: Long-Term Debt Issued, Total | H21: 362586 | I21: 273932.6 | J21: 279409.3 | K21: 231254.3 | L21: 464970.1
B22: Total Debt Repaid | H22: -453727 | I22: -362136.4 | J22: -332183.3 | K22: -276876.9 | L22: -313447.1
B23: Short Term Debt Repaid, Total | H23: - | I23: - | J23: - | K23: - | L23: -
B24: Long-Term Debt Repaid, Total | H24: -453727 | I24: -362136.4 | J24: -332183.3 | K24: -276876.9 | L24: -313447.1
B25: Issuance of Common Stock | H25: 158.5 | I25: 109.7 | J25: 103.1 | K25: 96.5 | L25: 93.2
B26: Repurchase of Common Stock | H26: - | I26: - | J26: - | K26: -122798.8 | L26: -
B27: Issuance of Preferred Stock | H27: - | I27: - | J27: - | K27: - | L27: -
B28: Repurchase of Preferred Stock | H28: - | I28: - | J28: - | K28: - | L28: -
B29: Common & Preferred Stock Dividends Paid | H29: -11232.3 | I29: -25283.8 | J29: -30914.2 | K29: -33735.6 | L29: -38495.7
B30: Special Dividend Paid | H30: -25276.6 | I30: - | J30: - | K30: -8433.9 | L30: -
B31: Other Financing Activities | H31: -50529 | I31: -38436.9 | J31: -35713.8 | K31: -52073.1 | L31: -47554.3
B32: Foreign Exchange Rate Adjustments | H32: -901.1 | I32: 823 | J32: 2636.8 | K32: 158.5 | L32: 286.8
B33: Miscellaneous Cash Flow Adjustments | H33: - | I33: - | J33: - | K33: - | L33: -
B34: Net Change in Cash | H34: 20489.5 | I34: 3967.2 | J34: 31564.5 | K34: -49681.9 | L34: 2285
B35: Beginning Cash Balance | H35: 113245.7 | I35: 133735.2 | J35: 137702.4 | K35: 169266.9 | L35: 119585
B36: Ending Cash Balance | H36: 133735.2 | I36: 137702.4 | J36: 169266.9 | K36: 119585 | L36: 121870
B37: Levered Free Cash Flow | H37: 165256.56 | I37: 74625.7 | J37: 116513.8 | K37: 247452.8 | L37: 98404.81
B38: Levered Free Cash Flow Growth | H38: 45.9172 | I38: -0.5484 | J38: 0.5613 | K38: 1.1238 | L38: -0.6023
B39: Free Cash Flow Yield | H39: 0.1067 | I39: 0.0646 | J39: 0.0613 | K39: 0.0263 | L39: 0.0099
A40: * In Millions of INR (except for per share items)

Sheet Sheet5
A1: LIQUIDITY RATIOS | B1: 2021 | C1: 2022 | D1: 2023 | E1: 2024 | F1: 2025
A2: current ratio | B2: ='Sheet 2'!H3/'Sheet 2'!H33 -> 1.4188898 | C2: ='Sheet 2'!I3/'Sheet 2'!I33 -> 1.3058349 | D2: ='Sheet 2'!J3/'Sheet 2'!J33 -> 1.3710731 | E2: ='Sheet 2'!K3/'Sheet 2'!K33 -> 1.2342006 | F2: ='Sheet 2'!L3/'Sheet 2'!L33 -> 1.2147379
A3: liquidity ratio | B3: =('Sheet 2'!H3-'Sheet 2'!H10)/'Sheet 2'!H33 -> 1.3765303 | C3: =('Sheet 2'!I3-'Sheet 2'!I10)/'Sheet 2'!I33 -> 1.2685589 | D3: =('Sheet 2'!J3-'Sheet 2'!J10)/'Sheet 2'!J33 -> 1.3289373 | E3: =('Sheet 2'!K3-'Sheet 2'!K10)/'Sheet 2'!K33 -> 1.1968215 | F3: =('Sheet 2'!L3-'Sheet 2'!L10)/'Sheet 2'!L33 -> 1.1767594
A5: SOLVANCY RATIO | B5: 2021 | C5: 2022 | D5: 2023 | E5: 2024 | F5: 2025
A6: Total Debt Ratio | B6: ='Sheet 2'!H44/'Sheet 2'!H17 -> 0.71754743 | C6: ='Sheet 2'!I44/'Sheet 2'!I17 -> 0.70201971 | D6: ='Sheet 2'!J44/'Sheet 2'!J17 -> 0.68649464 | E6: ='Sheet 2'!K44/'Sheet 2'!K17 -> 0.69850392 | F6: ='Sheet 2'!L44/'Sheet 2'!L17 -> 0.69592529
A7: Long term debt ratio | B7: ='Sheet 2'!H46/'Sheet 2'!H17 -> 0.26381939 | C7: ='Sheet 2'!I46/'Sheet 2'!I17 -> 0.19251677 | D7: ='Sheet 2'!J46/'Sheet 2'!J17 -> 0.18531028 | E7: ='Sheet 2'!K46/'Sheet 2'!K17 -> 0.16613053 | F7: ='Sheet 2'!L46/'Sheet 2'!L17 -> 0.15151433
A8: Long term debt to market cap | B8: ='Sheet 2'!H46/('Sheet 2'!H46+'Sheet 2'!H59) -> 0.99659094 | C8: ='Sheet 2'!I46/('Sheet 2'!I46+'Sheet 2'!I59) -> 0.99546021 | D8: ='Sheet 2'!J46/('Sheet 2'!J46+'Sheet 2'!J59) -> 0.99542918 | E8: ='Sheet 2'!K46/('Sheet 2'!K46+'Sheet 2'!K59) -> 0.99515814 | F8: ='Sheet 2'!L46/('Sheet 2'!L46+'Sheet 2'!L59) -> 0.99523974
A9: Debt to equity | B9: ='Sheet 2'!H68/'Sheet 2'!H53 -> 1.2154592 | C9: ='Sheet 2'!I68/'Sheet 2'!I53 -> 0.99640771 | D9: ='Sheet 2'!J68/'Sheet 2'!J53 -> 0.86662672 | E9: ='Sheet 2'!K68/'Sheet 2'!K53 -> 0.86287902 | F9: ='Sheet 2'!L68/'Sheet 2'!L53 -> 0.83660781
A10: Ltd to equity | B10: ='Sheet 2'!H46/'Sheet 2'!H59 -> 292.33577 | C10: ='Sheet 2'!I46/'Sheet 2'!I59 -> 219.27444 | D10: ='Sheet 2'!J46/'Sheet 2'!J59 -> 217.77901 | E10: ='Sheet 2'!K46/'Sheet 2'!K59 -> 205.53221 | F10: ='Sheet 2'!L46/'Sheet 2'!L59 -> 209.07264
A12: COVERAGE RATIO | B12: 2021 | C12: 2022 | D12: 2023 | E12: 2024 | F12: 2025
A13: Times Interest Earned | B13: ='Sheet 1'!H86/'Sheet 1'!H30*-1 -> 4.1432768 | C13: ='Sheet 1'!I86/'Sheet 1'!I30*-1 -> 5.7327831 | D13: ='Sheet 1'!J86/'Sheet 1'!J30*-1 -> 6.3684449 | E13: ='Sheet 1'!K86/'Sheet 1'!K30*-1 -> 6.7590562 | F13: ='Sheet 1'!L86/'Sheet 1'!L30*-1 -> 7.9307592
A14: Cash coverage ratio | B14: =('Sheet 1'!H19+'Sheet 1'!H86)/'Sheet 1'!H26 -> -4.138321 | C14: =('Sheet 1'!I19+'Sheet 1'!I86)/'Sheet 1'!I26 -> -5.7261915 | D14: =('Sheet 1'!J19+'Sheet 1'!J86)/'Sheet 1'!J26 -> -6.3638944 | E14: =('Sheet 1'!K19+'Sheet 1'!K86)/'Sheet 1'!K26 -> -6.7566697 | F14: =('Sheet 1'!L19+'Sheet 1'!L86)/'Sheet 1'!L26 -> -7.9284445
A16: EFFICIENCY RATIOS | B16: 2021 | C16: 2022 | D16: 2023 | E16: 2024 | F16: 2025
A17: Invetory turnover | B17: ='Sheet 1'!H7/'Sheet 2'!H10 -> 14.988046 | C17: ='Sheet 1'!I7/'Sheet 2'!I10 -> 16.384928 | D17: ='Sheet 1'!J7/'Sheet 2'!J10 -> 16.60628 | E17: ='Sheet 1'!K7/'Sheet 2'!K10 -> 21.330897 | F17: ='Sheet 1'!L7/'Sheet 2'!L10 -> 21.488566
A18: Receivable turnover | B18: - | C18: - | D18: - | E18: - | F18: -
A19: Credit purchase | B19: ='Sheet 2'!H34/'Sheet 1'!H3 -> 0.32833134 | C19: ='Sheet 2'!I34/'Sheet 1'!I3 -> 0.3235618 | D19: ='Sheet 2'!J34/'Sheet 1'!J3 -> 0.26737762 | E19: ='Sheet 2'!K34/'Sheet 1'!K3 -> 0.23665846 | F19: ='Sheet 2'!L34/'Sheet 1'!L3 -> 0.20191711
A20: Fixed turnover ratio | B20: ='Sheet 2'!H19 -> 137961.9 | C20: ='Sheet 2'!I19 -> 137378.1 | D20: ='Sheet 2'!J19 -> 164232.4 | E20: ='Sheet 2'!K19 -> 184840.9 | F20: ='Sheet 2'!L19 -> 193884.4
A21: Total asset tornover | B21: ='Sheet 2'!H3/'Sheet 2'!H17 -> 0.62635174 | C21: ='Sheet 2'!I3/'Sheet 2'!I17 -> 0.65049794 | D21: ='Sheet 2'!J3/'Sheet 2'!J17 -> 0.67262832 | E21: ='Sheet 2'!K3/'Sheet 2'!K17 -> 0.64265064 | F21: ='Sheet 2'!L3/'Sheet 2'!L17 -> 0.64644567
A22: Inventory days | B22: =1/Sheet5!B17*360 -> 24.019142 | C22: =1/Sheet5!C17*360 -> 21.971412 | D22: =1/Sheet5!D17*360 -> 21.678546 | E22: =1/Sheet5!E17*360 -> 16.876928 | F22: =1/Sheet5!F17*360 -> 16.753096
A23: Payable days | B23: =1/B19*360 -> 1096.4534 | C23: =1/C19*360 -> 1112.6159 | D23: =1/D19*360 -> 1346.4103 | E23: =1/E19*360 -> 1521.1795 | F23: =1/F19*360 -> 1782.9098
A24: Receivables | B24: - | C24: - | D24: - | E24: - | F24: -
A26: PROFITABILITY RATIOS | B26: 2021 | C26: 2022 | D26: 2023 | E26: 2024 | F26: 2025
A27: Gross profit margin | B27: ='Sheet 1'!H13 -> 0.3739 | C27: ='Sheet 1'!I13 -> 0.3866 | D27: ='Sheet 1'!J13 -> 0.391 | E27: ='Sheet 1'!K13 -> 0.3729 | F27: ='Sheet 1'!L13 -> 0.3656
A28: Operating profit margin | B28: ='Sheet 1'!H20/'Sheet 1'!H3*100 -> 11.611287 | C28: ='Sheet 1'!I20/'Sheet 1'!I3*100 -> 11.033699 | D28: ='Sheet 1'!J20/'Sheet 1'!J3*100 -> 10.868704 | E28: ='Sheet 1'!K20/'Sheet 1'!K3*100 -> 10.614848 | F28: ='Sheet 1'!L20/'Sheet 1'!L3*100 -> 10.167609
A29: Net profit margin | B29: ='Sheet 1'!H58 -> 0.0831 | C29: ='Sheet 1'!I58 -> 0.0546 | D29: ='Sheet 1'!J58 -> 0.0562 | E29: ='Sheet 1'!K58 -> 0.058 | F29: ='Sheet 1'!L58 -> 0.0579
A30: Return on asset | B30: ='Sheet 2'!H17 -> 3112737.1 | C30: ='Sheet 2'!I17 -> 3200672.4 | D30: ='Sheet 2'!J17 -> 3303523.1 | E30: ='Sheet 2'!K17 -> 3401359.7 | F30: ='Sheet 2'!L17 -> 3795241
A31: Return on equity | B31: ='Sheet 1'!H86/'Sheet 2'!H53 -> 0.1840034 | C31: ='Sheet 1'!I86/'Sheet 2'!I53 -> 0.18365707 | D31: ='Sheet 1'!J86/'Sheet 2'!J53 -> 0.19539851 | E31: ='Sheet 1'!K86/'Sheet 2'!K53 -> 0.23309166 | F31: ='Sheet 1'!L86/'Sheet 2'!L53 -> 0.22890163

Sheet  ASSUMPTIONS AND CONCLUSION
A1: ASSUMPTIONS
A2: The financial data provided for L&T (2021–2025) is accurate and reliable.
A3: Ratios are calculated using standard financial formulas (e.g., Current Ratio = Current Assets / Current Liabilities).
A4: Inflation, taxation, and external macroeconomic shocks are not considered in ratio interpretation.
A5: The analysis assumes that accounting policies and reporting standards remain consistent across years.
A6: Non-financial factors (like government policies, industry competition, geopolitical risks) are not included in the ratio analysis.
A7: Ratios are interpreted under the assumption that higher liquidity and lower leverage generally indicate financial strength.
A8: Any missing or inconsistent data points have been treated as negligible for overall analysis.
A11: CONCLUSION
A12: Revenue Growth: L&T has shown strong revenue growth from 2021 to 2025, highlighting its expanding business operations.
A13: Liquidity Position: The current ratio and quick ratio remain above 1 throughout, indicating that the company has enough short-term assets to cover its short-term liabilities, though the trend shows a slight decline in liquidity over time.
A14: Solvency: The debt ratio hovers around 0.70, meaning about 70% of the company’s assets are financed by debt. This shows moderate financial risk, but still manageable given L&T’s size and reputation.
... A16: Overall: L&T is financially strong, with consistent revenue growth and stable solvency. However, the company should monitor its liquidity and cash flow position to maintain operational efficiency.

Sheet DDM
B1: DIVIDEND DISCOUNT MODEL
B2: Larsen & Tubro
B3: Year | C3: Annual Dividend | D3: Growth | E3: Discounted Cash Flow | F3: Terminal Value | G3: Discounted Terminal Value
B4: 2030 | F4: =C5*(1+C27)/(C28-C27) -> 647.18157 | G4: =F4/(1+C28)^5 -> 169.68686
B5: 2030 | C5: =C6+($C$27*C6) -> 9.7340463 | D5: =(C5-C6)/C6 -> 0.28763313 | E5: =C5/((1+$C$28)^5) -> 2.5522045
B6: 2029 | C6: =C7+($C$27*C7) -> 7.5596426 | D6: =(C6-C7)/C7 -> 0.28763313 | E6: =C6/((1+$C$28)^4) -> 2.5905914
B7: 2028 | C7: =C8+($C$27*C8) -> 5.87096 | D7: =(C7-C8)/C8 -> 0.28763313 | E7: =C7/((1+$C$28)^3) -> 2.6295556
B8: 2027 | C8: =C9+($C$27*C9) -> 4.5594975 | D8: =(C8-C9)/C9 -> 0.28763313 | E8: =C8/((1+$C$28)^2) -> 2.6691059
B9: 2026 | C9: =C10+($C$27*C10) -> 3.5409911 | D9: =(C9-C10)/C10 -> 0.28763313 | E9: =C9/((1+$C$28)^1) -> 2.709251
B10: 45804 | C10: 2.75 | D10: =(C10-C11)/C11 -> 0.1
B11: 45461 | C11: 2.5 | D11: =(C11-C12)/C12 -> 0.25
B12: 45128 | C12: 2 | D12: =(C12-C13)/C13 -> 3
B13: 44743 | C13: 0.5 | D13: =(C13-C14)/C14 -> -0.40270194
B14: 43916 | C14: 0.837103 | D14: =(C14-C15)/C15 -> -0.09999957
B15: 43665 | C15: 0.930114 | D15: =(C15-C16)/C16 -> 0
B16: 43332 | C16: 0.930114 | D16: =(C16-C17)/C17 -> 0.25000034
B17: 42965 | C17: 0.744091 | D17: =(C17-C18)/C18 -> 0
B18: 42594 | C18: 0.744091 | D18: =(C18-C19)/C19 -> 0
B19: 42248 | C19: 0.744091 | D19: =(C19-C20)/C20 -> 0.066665615
B20: 41838 | C20: 0.697586 | D20: =(C20-C21)/C21 -> 0
B21: 41481 | C21: 0.697586
B27: Growth (g) | C27: =AVERAGE(D10:D20) -> 0.28763313
B28: Required Return (r) | C28: 0.307
B30: Actual Price | C30: 304.5
B32: DDM Price (A) | C32: =SUM(E5:E9)+G4 -> 182.83756
B33: Overvalued (or) Undervalued | C33: =IF(C32>C30,"UNDERVALUED","OVERVALUED") -> OVERVALUED
B36: Note: Price = C4/(r - g)
